<robot name="robotic-arm-3dof" version="1.0">
  <joint name="joint_1" type="revolute">
    <limit lower="-3.14000" upper="3.14000" effort="0.00000" velocity="0.00000"/>
    <origin rpy="0.00000 0.00000 0.00000" xyz="0.00000 0.00000 0.20000"/>
    <parent link="Cylinder_link"/>
    <child link="Cylinder.001_link"/>
    <axis xyz="0.00000 0.00000 1.00000"/>
  </joint>
  <joint name="joint_2" type="revolute">
    <limit lower="-3.14000" upper="3.14000" effort="0.00000" velocity="0.00000"/>
    <origin rpy="0.00000 0.00000 0.00000" xyz="2.50000 0.00000 0.00000"/>
    <parent link="Cylinder.001_link"/>
    <child link="Cylinder.002_link"/>
    <axis xyz="0.00000 1.00000 0.00000"/>
  </joint>
  <joint name="joint_3" type="revolute">
    <limit lower="-3.14000" upper="3.14000" effort="0.00000" velocity="0.00000"/>
    <origin rpy="0.00000 0.00000 0.00000" xyz="1.20000 0.00000 0.00000"/>
    <parent link="Cylinder.002_link"/>
    <child link="Cylinder.003_link"/>
    <axis xyz="0.00000 1.00000 0.00000"/>
  </joint>
  <link name="Cylinder.001_link">
    <collision name="Cylinder.001_collision">
      <origin rpy="0.00000 0.00000 0.00000" xyz="1.00000 0.00000 0.00000"/>
      <geometry>
        <box size="2.66965 0.80000 0.20000"/>
      </geometry>
    </collision>
    <inertial>
      <inertia ixx="0.02723" ixy="0.00000" ixz="0.00000" iyy="0.58138" iyz="-0.00000" izz="0.60282"/>
      <origin rpy="0.00000 0.00000 0.00000" xyz="0.53846 -0.00000 0.00000"/>
      <mass value="1.00000"/>
    </inertial>
    <visual name="Cylinder.001">
      <origin rpy="0.00000 0.00000 0.00000" xyz="0.00000 0.00000 0.00000"/>
      <geometry>
        <mesh filename="../meshes/obj/Cylinder.001.obj" scale="1.00000 1.00000 1.00000"/>
      </geometry>
    </visual>
  </link>
  <link name="Cylinder.002_link">
    <collision name="Cylinder.002_collision">
      <origin rpy="0.00000 0.00000 0.00000" xyz="0.45000 0.00000 0.00000"/>
      <geometry>
        <box size="1.22719 0.40000 0.40000"/>
      </geometry>
    </collision>
    <inertial>
      <inertia ixx="0.01588" ixy="-0.00000" ixz="0.00000" iyy="0.12671" iyz="-0.00000" izz="0.12900"/>
      <origin rpy="0.00000 0.00000 0.00000" xyz="0.23077 0.00000 0.00000"/>
      <mass value="1.00000"/>
    </inertial>
    <visual name="Cylinder.002">
      <origin rpy="0.00000 0.00000 0.00000" xyz="0.00000 0.00000 0.00000"/>
      <geometry>
        <mesh filename="../meshes/obj/Cylinder.003.obj" scale="1.00000 1.00000 1.00000"/>
      </geometry>
    </visual>
  </link>
  <link name="Cylinder.003_link">
    <collision name="Cylinder.003_collision">
      <origin rpy="0.00000 0.00000 0.00000" xyz="0.00000 0.00000 -0.36250"/>
      <geometry>
        <box size="0.30000 0.30000 1.02500"/>
      </geometry>
    </collision>
    <inertial>
      <inertia ixx="0.08836" ixy="-0.00000" ixz="0.00000" iyy="0.08734" iyz="0.00000" izz="0.00864"/>
      <origin rpy="0.00000 0.00000 0.00000" xyz="0.00000 -0.00000 -0.26316"/>
      <mass value="1.00000"/>
    </inertial>
    <visual name="Cylinder.003">
      <origin rpy="0.00000 0.00000 0.00000" xyz="0.00000 0.00000 0.00000"/>
      <geometry>
        <mesh filename="../meshes/obj/Cylinder.004.obj" scale="1.00000 1.00000 1.00000"/>
      </geometry>
    </visual>
  </link>
  <link name="Cylinder_link">
    <inertial>
      <inertia ixx="0.00001" ixy="0.00000" ixz="0.00000" iyy="0.00001" iyz="0.00000" izz="0.00001"/>
      <origin rpy="0.00000 0.00000 0.00000" xyz="0.00000 0.00000 0.00000"/>
      <mass value="0.00001"/>
    </inertial>
    <visual name="Cylinder">
      <origin rpy="0.00000 0.00000 0.00000" xyz="0.00000 0.00000 0.00000"/>
      <geometry>
        <mesh filename="../meshes/obj/Cylinder.obj" scale="1.00000 1.00000 1.00000"/>
      </geometry>
    </visual>
  </link>
</robot>